Workbook

Sheet README
A1: AEGIS — Financial Model v1.0 (24-month projection)
A2: Built 2026-05-05 from the operator brief and docs/CAPACITY_PLAN.md §11
A4: PURPOSE
A5: Forecast revenue, cost, and cash for AEGIS through Phase 1 GA + 12 months of growth, sized so the free-trial design and pricing tiers can be defended to investors and used as a marketing wedge.
A7: HOW TO USE
A8: 1. Open 'Assumptions' and adjust any BLUE cell. Yellow-highlighted cells are the highest-leverage knobs.
A9: 2. Watch results flow into PnL_24mo, CashFlow_24mo, and Scenarios automatically.
A10: 3. Switch the scenario selector on 'Scenarios' (cell B3) between Bear / Base / Bull to see funnel sensitivity.
A12: TAB MAP
A13: Assumptions — every input the operator can flex; pricing, trial size, conversion, churn, ARPU mix
A14: Cost_Stack — monthly stack reconciliation: $223 Claude Max + $20 Codex + Anthropic API + KLYTICS shared infra + AEGIS-only infra
A15: Trial_Economics — what one free trial costs us, implied CAC ceiling, payback math
... A41: • Does not split federal vs state tax. Effective tax rate is a single blue input on Assumptions.

Sheet Assumptions
A1: Assumptions — every blue cell is operator-editable
A3: Driver | B3: Value | C3: Source / rationale
A4: PRICING & PACKAGING
A5: Dev tier monthly price (USD) | B5: 49 | C5: Operator decision 2026-05-05 (overrides OD-003 default).
A6: Dev tier verifies included / mo | B6: 50000 | C6: Mirrors prior OD-003 option (Dev $49 / 50K).
A7: Team tier monthly price (USD) | B7: 299 | C7: Operator decision 2026-05-05.
A8: Team tier verifies included / mo | B8: 500000 | C8: Mirrors OD-003 Growth-tier verify cap.
A9: Scale tier monthly price (USD) | B9: 1499 | C9: Operator decision 2026-05-05; lands between OD-003's Growth and Enterprise.
A10: Scale tier verifies included / mo | B10: 5000000 | C10: Reflects spec § Part V Growth-tier headroom.
A11: Overage price per verify (USD) | B11: 0.0008 | C11: Operator decision 2026-05-05. 160x marginal cost ($5/M = $0.000005).
A12: Free-trial verify cap (per principal) | B12: 10000 | C12: Usage-capped, no time limit. Conversion trigger = hitting cap.
A14: COST OF GOODS SOLD (variable)
A15: Per-1M-verify marginal compute (USD) | B15: 5 | C15: docs/CAPACITY_PLAN.md §11.2 (CF Workers + KMS sign + Postgres insert).
A16: KMS sign cost reduction from M-038 batch | B16: 0.5 | C16: Pre-aggregation drops dominant KMS term ~10x; assume 50% effective once shipped.
A17: Stripe + payment processing rate | B17: 0.029 | C17: Stripe standard 2.9% + $0.30 per charge; $0.30 absorbed in fixed billing fee below.
A18: Stripe per-transaction fixed (USD) | B18: 0.3 | C18: Stripe standard.
A20: OPERATOR PERSONAL STACK (fixed monthly)
A21: Claude Max plan (USD/mo) | B21: 223 | C21: Operator brief 2026-05-05.
A22: Codex / OpenAI subscription (USD/mo) | B22: 20 | C22: Operator brief 2026-05-05.
A23: Anthropic API spend baseline (USD/mo) | B23: 350 | C23: Development + agent ops via API. Variable; this is steady-state baseline.
A24: Anthropic API growth multiplier per 6mo | B24: 1.4 | C24: API spend grows ~40% every 6 months as agent fleet scales.
A26: KLYTICS SHARED INFRASTRUCTURE (allocated to AEGIS)
A27: Total KLYTICS infra spend (USD/mo) | B27: 340 | C27: Vercel Pro + Supabase Pro + Railway team + GitHub Team + Cloudflare Pro + Sentry + PostHog + domains. Adjust as line items move.
A28: Allocation share to AEGIS (%) | B28: 0.4 | C28: AEGIS is one of three projects on KLYTICS infra (AEGIS / ComplianceKit / APEX). Allocation reflects expected verify-traffic share.
A30: AEGIS-SPECIFIC INFRA (scales with verify volume)
A31: Railway API pods baseline (USD/mo) | B31: 120 | C31: Phase 1 GA midpoint of $80–$300 range from CAPACITY_PLAN §11.1.
A32: Railway Postgres baseline (USD/mo) | B32: 250 | C32: CAPACITY_PLAN §11.1.
A33: Redis + BullMQ (USD/mo) | B33: 30 | C33: CAPACITY_PLAN §11.1 typical.
A34: KMS / GCP signing baseline (USD/mo) | B34: 40 | C34: Audit chain Ed25519 signing baseline (volume-scaled term lives in COGS row).
A35: Cloudflare Workers baseline (USD/mo) | B35: 25 | C35: Phase 3 edge verify path; minimal at GA.
A36: Observability (Sentry/Datadog) (USD/mo) | B36: 50 | C36: Sentry Team + log retention.
A37: Infra scaling factor at 1M verifies/mo (multiplier) | B37: 1 | C37: Baseline. At 10M verifies/mo, infra ~1.6x. At 100M, ~3.5x. Linear interp on Cost_Stack.
A39: HEADCOUNT / CONTRACTORS
A40: Operator draw / salary (USD/mo) | B40: 0 | C40: Operator runs lean; set to 0 until cash-flow break-even. Edit when comp begins.
A41: Contractor / freelance budget (USD/mo) | B41: 500 | C41: Design, content, occasional eng support.
A42: Contractor budget ramp at month 13 (multiplier) | B42: 4 | C42: Year-2 step-up as wedge accelerates.
A44: SALES & MARKETING
A45: Paid acquisition (USD/mo) months 1-6 | B45: 200 | C45: Founder-led GTM; minimal paid spend in early months.
A46: Paid acquisition (USD/mo) months 7-12 | B46: 1500 | C46: Switch on retargeting + LinkedIn after PMF signal.
A47: Paid acquisition (USD/mo) months 13-24 | B47: 5000 | C47: Year-2 wedge: paid funnels into 3-line-of-code quickstart.
...

Sheet Cost_Stack
A1: Cost Stack — monthly stack reconciled to operator brief
A2: All numbers flow from Assumptions; nothing is hardcoded here except month labels.
A4: Cost line | B4: M01 | C4: M02 | D4: M03 | E4: M04 | F4: M05 | G4: M06 | H4: M07 | I4: M08 | J4: M09 | K4: M10 | L4: M11 | M4: M12 | N4: M13 | O4: M14 | P4: M15 | Q4: M16 | R4: M17 | S4: M18 | T4: M19 | U4: M20 | V4: M21 | W4: M22 | X4: M23 | Y4: M24 | Z4: 24mo total
A5: OPERATOR PERSONAL STACK
A6: Claude Max plan | B6: =Assumptions!$B$21 -> 223 | C6: =Assumptions!$B$21 -> 223 | D6: =Assumptions!$B$21 -> 223 | E6: =Assumptions!$B$21 -> 223 | F6: =Assumptions!$B$21 -> 223 | G6: =Assumptions!$B$21 -> 223 | H6: =Assumptions!$B$21 -> 223 | I6: =Assumptions!$B$21 -> 223 | ... Y6: =Assumptions!$B$21 -> 223 | Z6: =SUM(B6:Y6) -> 5352
A7: Codex / OpenAI | B7: =Assumptions!$B$22 -> 20 | C7: =Assumptions!$B$22 -> 20 | D7: =Assumptions!$B$22 -> 20 | E7: =Assumptions!$B$22 -> 20 | F7: =Assumptions!$B$22 -> 20 | G7: =Assumptions!$B$22 -> 20 | H7: =Assumptions!$B$22 -> 20 | I7: =Assumptions!$B$22 -> 20 | ... Y7: =Assumptions!$B$22 -> 20 | Z7: =SUM(B7:Y7) -> 480
A8: Anthropic API (variable, ramps every 6mo) | B8: =Assumptions!$B$23*POWER(Assumptions!$B$24,0) -> 350 | C8: =Assumptions!$B$23*POWER(Assumptions!$B$24,0) -> 350 | D8: =Assumptions!$B$23*POWER(Assumptions!$B$24,0) -> 350 | E8: =Assumptions!$B$23*POWER(Assumptions!$B$24,0) -> 350 | F8: =Assumptions!$B$23*POWER(Assumptions!$B$24,0) -> 350 | G8: =Assumptions!$B$23*POWER(Assumptions!$B$24,0) -> 350 | H8: =Assumptions!$B$23*POWER(Assumptions!$B$24,1) -> 490 | I8: =Assumptions!$B$23*POWER(Assumptions!$B$24,1) -> 490 | J8: =Assumptions!$B$23*POWER(Assumptions!$B$24,1) -> 490 | K8: =Assumptions!$B$23*POWER(Assumptions!$B$24,1) -> 490 | L8: =Assumptions!$B$23*POWER(Assumptions!$B$24,1) -> 490 | M8: =Assumptions!$B$23*POWER(Assumptions!$B$24,1) -> 490 | N8: =Assumptions!$B$23*POWER(Assumptions!$B$24,2) -> 686 | O8: =Assumptions!$B$23*POWER(Assumptions!$B$24,2) -> 686 | P8: =Assumptions!$B$23*POWER(Assumptions!$B$24,2) -> 686 | Q8: =Assumptions!$B$23*POWER(Assumptions!$B$24,2) -> 686 | R8: =Assumptions!$B$23*POWER(Assumptions!$B$24,2) -> 686 | S8: =Assumptions!$B$23*POWER(Assumptions!$B$24,2) -> 686 | T8: =Assumptions!$B$23*POWER(Assumptions!$B$24,3) -> 960.4 | U8: =Assumptions!$B$23*POWER(Assumptions!$B$24,3) -> 960.4 | V8: =Assumptions!$B$23*POWER(Assumptions!$B$24,3) -> 960.4 | W8: =Assumptions!$B$23*POWER(Assumptions!$B$24,3) -> 960.4 | X8: =Assumptions!$B$23*POWER(Assumptions!$B$24,3) -> 960.4 | Y8: =Assumptions!$B$23*POWER(Assumptions!$B$24,3) -> 960.4 | Z8: =SUM(B8:Y8) -> 14918.4
A9: KLYTICS SHARED INFRA (allocated)
A10: KLYTICS infra share to AEGIS | B10: =Assumptions!$B$27*Assumptions!$B$28 -> 136 | C10: =Assumptions!$B$27*Assumptions!$B$28 -> 136 | D10: =Assumptions!$B$27*Assumptions!$B$28 -> 136 | E10: =Assumptions!$B$27*Assumptions!$B$28 -> 136 | F10: =Assumptions!$B$27*Assumptions!$B$28 -> 136 | G10: =Assumptions!$B$27*Assumptions!$B$28 -> 136 | H10: =Assumptions!$B$27*Assumptions!$B$28 -> 136 | I10: =Assumptions!$B$27*Assumptions!$B$28 -> 136 | ... Y10: =Assumptions!$B$27*Assumptions!$B$28 -> 136 | Z10: =SUM(B10:Y10) -> 3264
A11: AEGIS-SPECIFIC INFRA (scales with verifies)
A12: Railway API pods (baseline × scale) | B12: =Assumptions!$B$31*MIN(3.5, MAX(1, 1 + SQRT(MAX(0, Funnel_24mo!B21 - 1)) * 0.1)) -> 128.27565 | C12: =Assumptions!$B$31*MIN(3.5, MAX(1, 1 + SQRT(MAX(0, Funnel_24mo!C21 - 1)) * 0.1)) -> 150.98664 | D12: =Assumptions!$B$31*MIN(3.5, MAX(1, 1 + SQRT(MAX(0, Funnel_24mo!D21 - 1)) * 0.1)) -> 169.23093 | E12: =Assumptions!$B$31*MIN(3.5, MAX(1, 1 + SQRT(MAX(0, Funnel_24mo!E21 - 1)) * 0.1)) -> 196.80662 | F12: =Assumptions!$B$31*MIN(3.5, MAX(1, 1 + SQRT(MAX(0, Funnel_24mo!F21 - 1)) * 0.1)) -> 221.65183 | G12: =Assumptions!$B$31*MIN(3.5, MAX(1, 1 + SQRT(MAX(0, Funnel_24mo!G21 - 1)) * 0.1)) -> 245.32065 | H12: =Assumptions!$B$31*MIN(3.5, MAX(1, 1 + SQRT(MAX(0, Funnel_24mo!H21 - 1)) * 0.1)) -> 282.69511 | I12: =Assumptions!$B$31*MIN(3.5, MAX(1, 1 + SQRT(MAX(0, Funnel_24mo!I21 - 1)) * 0.1)) -> 320.09841 | ... Y12: =Assumptions!$B$31*MIN(3.5, MAX(1, 1 + SQRT(MAX(0, Funnel_24mo!Y21 - 1)) * 0.1)) -> 420 | Z12: =SUM(B12:Y12) -> 8346.9825
A13: Railway Postgres (baseline × scale) | B13: =Assumptions!$B$32*MIN(3.5, MAX(1, 1 + SQRT(MAX(0, Funnel_24mo!B21 - 1)) * 0.1)) -> 267.24094 | C13: =Assumptions!$B$32*MIN(3.5, MAX(1, 1 + SQRT(MAX(0, Funnel_24mo!C21 - 1)) * 0.1)) -> 314.5555 | D13: =Assumptions!$B$32*MIN(3.5, MAX(1, 1 + SQRT(MAX(0, Funnel_24mo!D21 - 1)) * 0.1)) -> 352.56444 | E13: =Assumptions!$B$32*MIN(3.5, MAX(1, 1 + SQRT(MAX(0, Funnel_24mo!E21 - 1)) * 0.1)) -> 410.01378 | F13: =Assumptions!$B$32*MIN(3.5, MAX(1, 1 + SQRT(MAX(0, Funnel_24mo!F21 - 1)) * 0.1)) -> 461.77465 | G13: =Assumptions!$B$32*MIN(3.5, MAX(1, 1 + SQRT(MAX(0, Funnel_24mo!G21 - 1)) * 0.1)) -> 511.08468 | H13: =Assumptions!$B$32*MIN(3.5, MAX(1, 1 + SQRT(MAX(0, Funnel_24mo!H21 - 1)) * 0.1)) -> 588.94814 | I13: =Assumptions!$B$32*MIN(3.5, MAX(1, 1 + SQRT(MAX(0, Funnel_24mo!I21 - 1)) * 0.1)) -> 666.87168 | ... Y13: =Assumptions!$B$32*MIN(3.5, MAX(1, 1 + SQRT(MAX(0, Funnel_24mo!Y21 - 1)) * 0.1)) -> 875 | Z13: =SUM(B13:Y13) -> 17389.547
A14: Redis + BullMQ | B14: =Assumptions!$B$33*MIN(3.5, MAX(1, 1 + SQRT(MAX(0, Funnel_24mo!B21 - 1)) * 0.1)) -> 32.068913 | C14: =Assumptions!$B$33*MIN(3.5, MAX(1, 1 + SQRT(MAX(0, Funnel_24mo!C21 - 1)) * 0.1)) -> 37.74666 | D14: =Assumptions!$B$33*MIN(3.5, MAX(1, 1 + SQRT(MAX(0, Funnel_24mo!D21 - 1)) * 0.1)) -> 42.307733 | E14: =Assumptions!$B$33*MIN(3.5, MAX(1, 1 + SQRT(MAX(0, Funnel_24mo!E21 - 1)) * 0.1)) -> 49.201654 | F14: =Assumptions!$B$33*MIN(3.5, MAX(1, 1 + SQRT(MAX(0, Funnel_24mo!F21 - 1)) * 0.1)) -> 55.412958 | G14: =Assumptions!$B$33*MIN(3.5, MAX(1, 1 + SQRT(MAX(0, Funnel_24mo!G21 - 1)) * 0.1)) -> 61.330162 | H14: =Assumptions!$B$33*MIN(3.5, MAX(1, 1 + SQRT(MAX(0, Funnel_24mo!H21 - 1)) * 0.1)) -> 70.673776 | I14: =Assumptions!$B$33*MIN(3.5, MAX(1, 1 + SQRT(MAX(0, Funnel_24mo!I21 - 1)) * 0.1)) -> 80.024601 | ... Y14: =Assumptions!$B$33*MIN(3.5, MAX(1, 1 + SQRT(MAX(0, Funnel_24mo!Y21 - 1)) * 0.1)) -> 105 | Z14: =SUM(B14:Y14) -> 2086.7456
A15: KMS signing baseline | B15: =Assumptions!$B$34 -> 40 | C15: =Assumptions!$B$34 -> 40 | D15: =Assumptions!$B$34 -> 40 | E15: =Assumptions!$B$34 -> 40 | F15: =Assumptions!$B$34 -> 40 | G15: =Assumptions!$B$34 -> 40 | H15: =Assumptions!$B$34 -> 40 | I15: =Assumptions!$B$34 -> 40 | ... Y15: =Assumptions!$B$34 -> 40 | Z15: =SUM(B15:Y15) -> 960
A16: Cloudflare Workers baseline | B16: =Assumptions!$B$35 -> 25 | C16: =Assumptions!$B$35 -> 25 | D16: =Assumptions!$B$35 -> 25 | E16: =Assumptions!$B$35 -> 25 | F16: =Assumptions!$B$35 -> 25 | G16: =Assumptions!$B$35 -> 25 | H16: =Assumptions!$B$35 -> 25 | I16: =Assumptions!$B$35 -> 25 | ... Y16: =Assumptions!$B$35 -> 25 | Z16: =SUM(B16:Y16) -> 600
A17: Observability | B17: =Assumptions!$B$36*MIN(3.5, MAX(1, 1 + SQRT(MAX(0, Funnel_24mo!B21 - 1)) * 0.1)) -> 53.448188 | C17: =Assumptions!$B$36*MIN(3.5, MAX(1, 1 + SQRT(MAX(0, Funnel_24mo!C21 - 1)) * 0.1)) -> 62.9111 | D17: =Assumptions!$B$36*MIN(3.5, MAX(1, 1 + SQRT(MAX(0, Funnel_24mo!D21 - 1)) * 0.1)) -> 70.512888 | E17: =Assumptions!$B$36*MIN(3.5, MAX(1, 1 + SQRT(MAX(0, Funnel_24mo!E21 - 1)) * 0.1)) -> 82.002756 | F17: =Assumptions!$B$36*MIN(3.5, MAX(1, 1 + SQRT(MAX(0, Funnel_24mo!F21 - 1)) * 0.1)) -> 92.35493 | G17: =Assumptions!$B$36*MIN(3.5, MAX(1, 1 + SQRT(MAX(0, Funnel_24mo!G21 - 1)) * 0.1)) -> 102.21694 | H17: =Assumptions!$B$36*MIN(3.5, MAX(1, 1 + SQRT(MAX(0, Funnel_24mo!H21 - 1)) * 0.1)) -> 117.78963 | I17: =Assumptions!$B$36*MIN(3.5, MAX(1, 1 + SQRT(MAX(0, Funnel_24mo!I21 - 1)) * 0.1)) -> 133.37434 | ... Y17: =Assumptions!$B$36*MIN(3.5, MAX(1, 1 + SQRT(MAX(0, Funnel_24mo!Y21 - 1)) * 0.1)) -> 175 | Z17: =SUM(B17:Y17) -> 3477.9094
A18: VARIABLE COGS (driven by verify volume)
A19: Variable compute @ verify volume | B19: =Funnel_24mo!B21*Assumptions!$B$15 -> 7.378 | C19: =Funnel_24mo!C21*Assumptions!$B$15 -> 38.3393 | D19: =Funnel_24mo!D21*Assumptions!$B$15 -> 89.155714 | E19: =Funnel_24mo!E21*Assumptions!$B$15 -> 209.83528 | F19: =Funnel_24mo!F21*Assumptions!$B$15 -> 363.78802 | G19: =Funnel_24mo!G21*Assumptions!$B$15 -> 550.32168 | H19: =Funnel_24mo!H21*Assumptions!$B$15 -> 924.08671 | I19: =Funnel_24mo!I21*Assumptions!$B$15 -> 1395.256 | J19: =Funnel_24mo!J21*(Assumptions!$B$15*(1-Assumptions!$B$16)) -> 980.90223 | K19: =Funnel_24mo!K21*(Assumptions!$B$15*(1-Assumptions!$B$16)) -> 1310.8791 | L19: =Funnel_24mo!L21*(Assumptions!$B$15*(1-Assumptions!$B$16)) -> 1686.5966 | M19: =Funnel_24mo!M21*(Assumptions!$B$15*(1-Assumptions!$B$16)) -> 2107.1164 | N19: =Funnel_24mo!N21*(Assumptions!$B$15*(1-Assumptions!$B$16)) -> 2582.4455 | O19: =Funnel_24mo!O21*(Assumptions!$B$15*(1-Assumptions!$B$16)) -> 3110.5634 | P19: =Funnel_24mo!P21*(Assumptions!$B$15*(1-Assumptions!$B$16)) -> 3690.3936 | Q19: =Funnel_24mo!Q21*(Assumptions!$B$15*(1-Assumptions!$B$16)) -> 4320.8863 | ... Y19: =Funnel_24mo!Y21*(Assumptions!$B$15*(1-Assumptions!$B$16)) -> 11070.835 | Z19: =SUM(B19:Y19) -> 86385.488
A20: HEADCOUNT & CONTRACTORS
A21: Operator draw | B21: =Assumptions!$B$40 -> 0 | C21: =Assumptions!$B$40 -> 0 | D21: =Assumptions!$B$40 -> 0 | E21: =Assumptions!$B$40 -> 0 | F21: =Assumptions!$B$40 -> 0 | G21: =Assumptions!$B$40 -> 0 | H21: =Assumptions!$B$40 -> 0 | I21: =Assumptions!$B$40 -> 0 | ... Y21: =Assumptions!$B$40 -> 0 | Z21: =SUM(B21:Y21) -> 0
A22: Contractor / freelance | B22: =Assumptions!$B$41 -> 500 | C22: =Assumptions!$B$41 -> 500 | D22: =Assumptions!$B$41 -> 500 | E22: =Assumptions!$B$41 -> 500 | F22: =Assumptions!$B$41 -> 500 | G22: =Assumptions!$B$41 -> 500 | H22: =Assumptions!$B$41 -> 500 | I22: =Assumptions!$B$41 -> 500 | ... M22: =Assumptions!$B$41 -> 500 | N22: =Assumptions!$B$41*Assumptions!$B$42 -> 2000 | O22: =Assumptions!$B$41*Assumptions!$B$42 -> 2000 | P22: =Assumptions!$B$41*Assumptions!$B$42 -> 2000 | Q22: =Assumptions!$B$41*Assumptions!$B$42 -> 2000 | R22: =Assumptions!$B$41*Assumptions!$B$42 -> 2000 | S22: =Assumptions!$B$41*Assumptions!$B$42 -> 2000 | T22: =Assumptions!$B$41*Assumptions!$B$42 -> 2000 | U22: =Assumptions!$B$41*Assumptions!$B$42 -> 2000 | ... Y22: =Assumptions!$B$41*Assumptions!$B$42 -> 2000 | Z22: =SUM(B22:Y22) -> 30000
A23: SALES & MARKETING
A24: Paid acquisition | B24: =Assumptions!$B$45 -> 200 | C24: =Assumptions!$B$45 -> 200 | D24: =Assumptions!$B$45 -> 200 | E24: =Assumptions!$B$45 -> 200 | F24: =Assumptions!$B$45 -> 200 | G24: =Assumptions!$B$45 -> 200 | H24: =Assumptions!$B$46 -> 1500 | I24: =Assumptions!$B$46 -> 1500 | J24: =Assumptions!$B$46 -> 1500 | K24: =Assumptions!$B$46 -> 1500 | L24: =Assumptions!$B$46 -> 1500 | M24: =Assumptions!$B$46 -> 1500 | N24: =Assumptions!$B$47 -> 5000 | O24: =Assumptions!$B$47 -> 5000 | P24: =Assumptions!$B$47 -> 5000 | Q24: =Assumptions!$B$47 -> 5000 | R24: =Assumptions!$B$47 -> 5000 | S24: =Assumptions!$B$47 -> 5000 | T24: =Assumptions!$B$47 -> 5000 | U24: =Assumptions!$B$47 -> 5000 | ... Y24: =Assumptions!$B$47 -> 5000 | Z24: =SUM(B24:Y24) -> 70200
A25: Conferences + community | B25: =Assumptions!$B$48 -> 300 | C25: =Assumptions!$B$48 -> 300 | D25: =Assumptions!$B$48 -> 300 | E25: =Assumptions!$B$48 -> 300 | F25: =Assumptions!$B$48 -> 300 | G25: =Assumptions!$B$48 -> 300 | H25: =Assumptions!$B$48 -> 300 | I25: =Assumptions!$B$48 -> 300 | ... Y25: =Assumptions!$B$48 -> 300 | Z25: =SUM(B25:Y25) -> 7200
A26: TOTAL MONTHLY STACK COST
A27: TOTAL stack cost | B27: =SUM(B6:B25) -> 2282.4117 | C27: =SUM(C6:C25) -> 2398.5392 | D27: =SUM(D6:D25) -> 2517.7717 | E27: =SUM(E6:E25) -> 2741.8601 | F27: =SUM(F6:F25) -> 2988.9824 | G27: =SUM(G6:G25) -> 3264.2741 | H27: =SUM(H6:H25) -> 5218.1934 | I27: =SUM(I6:I25) -> 5829.625 | ... Y27: =SUM(Y6:Y25) -> 21350.235 | Z27: =SUM(B27:Y27) -> 250661.07

Sheet Trial_Economics
A1: Free-Trial Economics — what one trial costs us, what it must return
A2: Drives conversion-rate threshold below which the free trial loses money.
A4: Metric | B4: Value | C4: Derivation
A5: Free verifies granted per trial | B5: =Assumptions!$B$12 -> 10000 | C5: Operator decision: usage-cap (10K), no time-cap. Conversion lever = hitting the cap.
A6: Marginal compute cost per verify (USD) | B6: =Assumptions!$B$15/1000000 -> 5e-06 | C6: $5/M ÷ 1M (CAPACITY_PLAN.md §11.2).
A7: Marginal compute cost of one full trial (USD) | B7: =B5*B6 -> 0.05 | C7: verifies × per-verify cost.
A8: Avg trial completion (% of cap actually used) | B8: 0.55 | C8: Most trials don't hit cap. Hardcoded blue input — flex on real data.
A9: Expected variable compute / trial (USD) | B9: =B7*B8 -> 0.0275 | C9: Compute × avg completion.
A10: Support + ops loaded cost / trial (USD) | B10: 0.4 | C10: Email support, doc hosting, fraud screening. Blue — flex over time.
A11: Paid-acquisition cost per trial (USD, blended) | B11: =SUM(Cost_Stack!B24:Y24)/Funnel_24mo!Z5 -> 0.83472057 | C11: Total paid-acq spend ÷ total trials. Patched after Funnel sheet built.
A12: Fully-loaded cost per trial (USD) | B12: =B9+B10+B11 -> 1.2622206 | C12: Variable + ops + acquisition.
A13: Blended ARPU month-1 (USD) | B13: =(Assumptions!$B$5*Assumptions!$B$60)+(Assumptions!$B$7*Assumptions!$B$61)+(Assumptions!$B$9*Assumptions!$B$62) -> 184 | C13: Mix-weighted average tier price.
A14: Implied break-even conversion rate (one-time, ARPU-based) | B14: =B12/B13 -> 0.0068598944 | C14: Cost-per-trial ÷ first-month ARPU.
A15: Blended LTV (USD, undiscounted) | B15: =UnitEcon!E15 -> 4791.3003 | C15: Cross-link to UnitEcon!E15 (blended NRR-adjusted LTV).
A16: Implied break-even conversion rate (LTV-based) | B16: =B12/B15 -> 0.00026344009 | C16: Cost-per-trial ÷ blended LTV. Lower = more headroom.
A17: Modeled conversion rate (steady state) | B17: =Assumptions!$B$57 -> 0.18 | C17: From Assumptions; compare to break-even rate above.
A18: Headroom (modeled − LTV-based break-even) | B18: =B17-B16 -> 0.17973656 | C18: Positive = trial is profitable in expectation.

Sheet Funnel_24mo
A1: Funnel — 24 months (BASE scenario; multipliers on Scenarios tab)
A2: Trial sign-ups → conversions → cumulative paid customers → verify volume.
A4: Metric | B4: M01 | C4: M02 | D4: M03 | E4: M04 | F4: M05 | G4: M06 | H4: M07 | I4: M08 | J4: M09 | K4: M10 | L4: M11 | M4: M12 | N4: M13 | O4: M14 | P4: M15 | Q4: M16 | R4: M17 | S4: M18 | T4: M19 | U4: M20 | V4: M21 | W4: M22 | X4: M23 | Y4: M24 | Z4: 24mo total
A5: Trial sign-ups | B5: =Assumptions!$B$51 -> 50 | C5: =Assumptions!$B$51+((Assumptions!$B$52-Assumptions!$B$51)*(2-1)/5) -> 220 | D5: =Assumptions!$B$51+((Assumptions!$B$52-Assumptions!$B$51)*(3-1)/5) -> 390 | E5: =Assumptions!$B$51+((Assumptions!$B$52-Assumptions!$B$51)*(4-1)/5) -> 560 | F5: =Assumptions!$B$51+((Assumptions!$B$52-Assumptions!$B$51)*(5-1)/5) -> 730 | G5: =Assumptions!$B$51+((Assumptions!$B$52-Assumptions!$B$51)*(6-1)/5) -> 900 | H5: =Assumptions!$B$52+((Assumptions!$B$53-Assumptions!$B$52)*(7-6)/6) -> 1250 | I5: =Assumptions!$B$52+((Assumptions!$B$53-Assumptions!$B$52)*(8-6)/6) -> 1600 | J5: =Assumptions!$B$52+((Assumptions!$B$53-Assumptions!$B$52)*(9-6)/6) -> 1950 | K5: =Assumptions!$B$52+((Assumptions!$B$53-Assumptions!$B$52)*(10-6)/6) -> 2300 | L5: =Assumptions!$B$52+((Assumptions!$B$53-Assumptions!$B$52)*(11-6)/6) -> 2650 | M5: =Assumptions!$B$52+((Assumptions!$B$53-Assumptions!$B$52)*(12-6)/6) -> 3000 | N5: =Assumptions!$B$53+((Assumptions!$B$54-Assumptions!$B$53)*(13-12)/12) -> 3416.6667 | O5: =Assumptions!$B$53+((Assumptions!$B$54-Assumptions!$B$53)*(14-12)/12) -> 3833.3333 | P5: =Assumptions!$B$53+((Assumptions!$B$54-Assumptions!$B$53)*(15-12)/12) -> 4250 | Q5: =Assumptions!$B$53+((Assumptions!$B$54-Assumptions!$B$53)*(16-12)/12) -> 4666.6667 | R5: =Assumptions!$B$53+((Assumptions!$B$54-Assumptions!$B$53)*(17-12)/12) -> 5083.3333 | S5: =Assumptions!$B$53+((Assumptions!$B$54-Assumptions!$B$53)*(18-12)/12) -> 5500 | T5: =Assumptions!$B$53+((Assumptions!$B$54-Assumptions!$B$53)*(19-12)/12) -> 5916.6667 | U5: =Assumptions!$B$53+((Assumptions!$B$54-Assumptions!$B$53)*(20-12)/12) -> 6333.3333 | V5: =Assumptions!$B$53+((Assumptions!$B$54-Assumptions!$B$53)*(21-12)/12) -> 6750 | W5: =Assumptions!$B$53+((Assumptions!$B$54-Assumptions!$B$53)*(22-12)/12) -> 7166.6667 | X5: =Assumptions!$B$53+((Assumptions!$B$54-Assumptions!$B$53)*(23-12)/12) -> 7583.3333 | Y5: =Assumptions!$B$53+((Assumptions!$B$54-Assumptions!$B$53)*(24-12)/12) -> 8000 | Z5: =SUM(B5:Y5) -> 84100
A6: Effective conversion rate | B6: =Assumptions!$B$57*Assumptions!$B$58 -> 0.072 | C6: =Assumptions!$B$57*Assumptions!$B$58 -> 0.072 | D6: =Assumptions!$B$57*Assumptions!$B$58 -> 0.072 | E6: =Assumptions!$B$57*Assumptions!$B$59 -> 0.126 | F6: =Assumptions!$B$57*Assumptions!$B$59 -> 0.126 | G6: =Assumptions!$B$57*Assumptions!$B$59 -> 0.126 | H6: =Assumptions!$B$57 -> 0.18 | I6: =Assumptions!$B$57 -> 0.18 | J6: =Assumptions!$B$57 -> 0.18 | K6: =Assumptions!$B$57 -> 0.18 | L6: =Assumptions!$B$57 -> 0.18 | M6: =Assumptions!$B$57 -> 0.18 | N6: =Assumptions!$B$57 -> 0.18 | O6: =Assumptions!$B$57 -> 0.18 | ... Y6: =Assumptions!$B$57 -> 0.18
A7: New paid customers | B7: =B5*B6 -> 3.6 | C7: =C5*C6 -> 15.84 | D7: =D5*D6 -> 28.08 | E7: =E5*E6 -> 70.56 | F7: =F5*F6 -> 91.98 | G7: =G5*G6 -> 113.4 | H7: =H5*H6 -> 225 | I7: =I5*I6 -> 288 | ... Y7: =Y5*Y6 -> 1440 | Z7: =SUM(B7:Y7) -> 14948.46
A8: ↳ new Dev tier | B8: =B7*Assumptions!$B$60 -> 2.52 | C8: =C7*Assumptions!$B$60 -> 11.088 | D8: =D7*Assumptions!$B$60 -> 19.656 | E8: =E7*Assumptions!$B$60 -> 49.392 | F8: =F7*Assumptions!$B$60 -> 64.386 | G8: =G7*Assumptions!$B$60 -> 79.38 | H8: =H7*Assumptions!$B$60 -> 157.5 | I8: =I7*Assumptions!$B$60 -> 201.6 | ... Y8: =Y7*Assumptions!$B$60 -> 1008 | Z8: =SUM(B8:Y8) -> 10463.922
A9: ↳ new Team tier | B9: =B7*Assumptions!$B$61 -> 0.9 | C9: =C7*Assumptions!$B$61 -> 3.96 | D9: =D7*Assumptions!$B$61 -> 7.02 | E9: =E7*Assumptions!$B$61 -> 17.64 | F9: =F7*Assumptions!$B$61 -> 22.995 | G9: =G7*Assumptions!$B$61 -> 28.35 | H9: =H7*Assumptions!$B$61 -> 56.25 | I9: =I7*Assumptions!$B$61 -> 72 | ... Y9: =Y7*Assumptions!$B$61 -> 360 | Z9: =SUM(B9:Y9) -> 3737.115
A10: ↳ new Scale tier | B10: =B7*Assumptions!$B$62 -> 0.18 | C10: =C7*Assumptions!$B$62 -> 0.792 | D10: =D7*Assumptions!$B$62 -> 1.404 | E10: =E7*Assumptions!$B$62 -> 3.528 | F10: =F7*Assumptions!$B$62 -> 4.599 | G10: =G7*Assumptions!$B$62 -> 5.67 | H10: =H7*Assumptions!$B$62 -> 11.25 | I10: =I7*Assumptions!$B$62 -> 14.4 | ... Y10: =Y7*Assumptions!$B$62 -> 72 | Z10: =SUM(B10:Y10) -> 747.423
A11: ACTIVE PAID CUSTOMERS (cohort with churn)
A12: Active Dev customers | B12: =B8 -> 2.52 | C12: =B12*(1-Assumptions!$B$63)+C8 -> 13.482 | D12: =C12*(1-Assumptions!$B$63)+D8 -> 32.4639 | E12: =D12*(1-Assumptions!$B$63)+E8 -> 80.232705 | F12: =E12*(1-Assumptions!$B$63)+F8 -> 140.60707 | G12: =F12*(1-Assumptions!$B$63)+G8 -> 212.95672 | H12: =G12*(1-Assumptions!$B$63)+H8 -> 359.80888 | I12: =H12*(1-Assumptions!$B$63)+I8 -> 543.41844 | J12: =I12*(1-Assumptions!$B$63)+J8 -> 761.94751 | ... Y12: =X12*(1-Assumptions!$B$63)+Y8 -> 7775.0543
A13: Active Team customers | B13: =B9 -> 0.9 | C13: =B13*(1-Assumptions!$B$64)+C9 -> 4.833 | D13: =C13*(1-Assumptions!$B$64)+D9 -> 11.70801 | E13: =D13*(1-Assumptions!$B$64)+E9 -> 28.99677 | F13: =E13*(1-Assumptions!$B$64)+F9 -> 51.121867 | G13: =F13*(1-Assumptions!$B$64)+G9 -> 77.938211 | H13: =G13*(1-Assumptions!$B$64)+H9 -> 131.85006 | I13: =H13*(1-Assumptions!$B$64)+I9 -> 199.89456 | J13: =I13*(1-Assumptions!$B$64)+J9 -> 281.64773 | ... Y13: =X13*(1-Assumptions!$B$64)+Y9 -> 3110.6233
A14: Active Scale customers | B14: =B10 -> 0.18 | C14: =B14*(1-Assumptions!$B$65)+C10 -> 0.9693 | D14: =C14*(1-Assumptions!$B$65)+D10 -> 2.3587605 | E14: =D14*(1-Assumptions!$B$65)+E10 -> 5.8513791 | F14: =E14*(1-Assumptions!$B$65)+F10 -> 10.362608 | G14: =F14*(1-Assumptions!$B$65)+G10 -> 15.877169 | H14: =G14*(1-Assumptions!$B$65)+H10 -> 26.889012 | I14: =H14*(1-Assumptions!$B$65)+I10 -> 40.885677 | J14: =I14*(1-Assumptions!$B$65)+J10 -> 57.822391 | ... Y14: =X14*(1-Assumptions!$B$65)+Y10 -> 680.52537
A15: Total active paid customers | B15: =B12+B13+B14 -> 3.6 | C15: =C12+C13+C14 -> 19.2843 | D15: =D12+D13+D14 -> 46.53067 | E15: =E12+E13+E14 -> 115.08085 | F15: =F12+F13+F14 -> 202.09154 | G15: =G12+G13+G14 -> 306.7721 | H15: =H12+H13+H14 -> 518.54796 | I15: =I12+I13+I14 -> 784.19868 | ... Y15: =Y12+Y13+Y14 -> 11566.203
A16: VERIFY VOLUME
A17: Paid verifies (M) — Dev | B17: =B12*Assumptions!$B$69*1000/1000000 -> 0.0756 | C17: =C12*Assumptions!$B$69*1000/1000000 -> 0.40446 | D17: =D12*Assumptions!$B$69*1000/1000000 -> 0.973917 | E17: =E12*Assumptions!$B$69*1000/1000000 -> 2.4069812 | F17: =F12*Assumptions!$B$69*1000/1000000 -> 4.2182121 | G17: =G12*Assumptions!$B$69*1000/1000000 -> 6.3887015 | H17: =H12*Assumptions!$B$69*1000/1000000 -> 10.794266 | I17: =I12*Assumptions!$B$69*1000/1000000 -> 16.302553 | ... Y17: =Y12*Assumptions!$B$69*1000/1000000 -> 233.25163
A18: Paid verifies (M) — Team | B18: =B13*Assumptions!$B$70*1000/1000000 -> 0.315 | C18: =C13*Assumptions!$B$70*1000/1000000 -> 1.69155 | D18: =D13*Assumptions!$B$70*1000/1000000 -> 4.0978035 | E18: =E13*Assumptions!$B$70*1000/1000000 -> 10.148869 | F18: =F13*Assumptions!$B$70*1000/1000000 -> 17.892653 | G18: =G13*Assumptions!$B$70*1000/1000000 -> 27.278374 | H18: =H13*Assumptions!$B$70*1000/1000000 -> 46.147523 | I18: =I13*Assumptions!$B$70*1000/1000000 -> 69.963097 | ... Y18: =Y13*Assumptions!$B$70*1000/1000000 -> 1088.7181
A19: Paid verifies (M) — Scale | B19: =B14*Assumptions!$B$71*1000/1000000 -> 0.81 | C19: =C14*Assumptions!$B$71*1000/1000000 -> 4.36185 | D19: =D14*Assumptions!$B$71*1000/1000000 -> 10.614422 | E19: =E14*Assumptions!$B$71*1000/1000000 -> 26.331206 | F19: =F14*Assumptions!$B$71*1000/1000000 -> 46.631738 | G19: =G14*Assumptions!$B$71*1000/1000000 -> 71.447262 | H19: =H14*Assumptions!$B$71*1000/1000000 -> 121.00055 | I19: =I14*Assumptions!$B$71*1000/1000000 -> 183.98554 | ... Y19: =Y14*Assumptions!$B$71*1000/1000000 -> 3062.3642
A20: Trial verifies (M) — free traffic | B20: =B5*Assumptions!$B$12*Trial_Economics!B8/1000000 -> 0.275 | C20: =C5*Assumptions!$B$12*Trial_Economics!B8/1000000 -> 1.21 | D20: =D5*Assumptions!$B$12*Trial_Economics!B8/1000000 -> 2.145 | E20: =E5*Assumptions!$B$12*Trial_Economics!B8/1000000 -> 3.08 | F20: =F5*Assumptions!$B$12*Trial_Economics!B8/1000000 -> 4.015 | G20: =G5*Assumptions!$B$12*Trial_Economics!B8/1000000 -> 4.95 | H20: =H5*Assumptions!$B$12*Trial_Economics!B8/1000000 -> 6.875 | I20: =I5*Assumptions!$B$12*Trial_Economics!B8/1000000 -> 8.8 | J20: =J5*Assumptions!$B$12*Trial_Economics!B8/1000000 -> 10.725 | K20: =K5*Assumptions!$B$12*Trial_Economics!B8/1000000 -> 12.65 | L20: =L5*Assumptions!$B$12*Trial_Economics!B8/1000000 -> 14.575 | M20: =M5*Assumptions!$B$12*Trial_Economics!B8/1000000 -> 16.5 | N20: =N5*Assumptions!$B$12*Trial_Economics!B8/1000000 -> 18.791667 | O20: =O5*Assumptions!$B$12*Trial_Economics!B8/1000000 -> 21.083333 | P20: =P5*Assumptions!$B$12*Trial_Economics!B8/1000000 -> 23.375 | Q20: =Q5*Assumptions!$B$12*Trial_Economics!B8/1000000 -> 25.666667 | R20: =R5*Assumptions!$B$12*Trial_Economics!B8/1000000 -> 27.958333 | S20: =S5*Assumptions!$B$12*Trial_Economics!B8/1000000 -> 30.25 | T20: =T5*Assumptions!$B$12*Trial_Economics!B8/1000000 -> 32.541667 | U20: =U5*Assumptions!$B$12*Trial_Economics!B8/1000000 -> 34.833333 | V20: =V5*Assumptions!$B$12*Trial_Economics!B8/1000000 -> 37.125 | W20: =W5*Assumptions!$B$12*Trial_Economics!B8/1000000 -> 39.416667 | X20: =X5*Assumptions!$B$12*Trial_Economics!B8/1000000 -> 41.708333 | Y20: =Y5*Assumptions!$B$12*Trial_Economics!B8/1000000 -> 44
A21: Total verifies (M) | B21: =B17+B18+B19+B20 -> 1.4756 | C21: =C17+C18+C19+C20 -> 7.66786 | D21: =D17+D18+D19+D20 -> 17.831143 | E21: =E17+E18+E19+E20 -> 41.967056 | F21: =F17+F18+F19+F20 -> 72.757603 | G21: =G17+G18+G19+G20 -> 110.06434 | H21: =H17+H18+H19+H20 -> 184.81734 | I21: =I17+I18+I19+I20 -> 279.05119 | ... Y21: =Y17+Y18+Y19+Y20 -> 4428.3339

Sheet PnL_24mo
A1: P&L — 24 months
A2: Revenue minus COGS minus OpEx; tax applied on positive months.
A4: Line | B4: M01 | C4: M02 | D4: M03 | E4: M04 | F4: M05 | G4: M06 | H4: M07 | I4: M08 | J4: M09 | K4: M10 | L4: M11 | M4: M12 | N4: M13 | O4: M14 | P4: M15 | Q4: M16 | R4: M17 | S4: M18 | T4: M19 | U4: M20 | V4: M21 | W4: M22 | X4: M23 | Y4: M24 | Z4: 24mo total
A5: REVENUE
A6: Subscription — Dev | B6: =Funnel_24mo!B12*Assumptions!$B$5 -> 123.48 | C6: =Funnel_24mo!C12*Assumptions!$B$5 -> 660.618 | D6: =Funnel_24mo!D12*Assumptions!$B$5 -> 1590.7311 | E6: =Funnel_24mo!E12*Assumptions!$B$5 -> 3931.4025 | F6: =Funnel_24mo!F12*Assumptions!$B$5 -> 6889.7464 | G6: =Funnel_24mo!G12*Assumptions!$B$5 -> 10434.879 | H6: =Funnel_24mo!H12*Assumptions!$B$5 -> 17630.635 | I6: =Funnel_24mo!I12*Assumptions!$B$5 -> 26627.503 | ... Y6: =Funnel_24mo!Y12*Assumptions!$B$5 -> 380977.66 | Z6: =SUM(B6:Y6) -> 3016068
A7: Subscription — Team | B7: =Funnel_24mo!B13*Assumptions!$B$7 -> 269.1 | C7: =Funnel_24mo!C13*Assumptions!$B$7 -> 1445.067 | D7: =Funnel_24mo!D13*Assumptions!$B$7 -> 3500.695 | E7: =Funnel_24mo!E13*Assumptions!$B$7 -> 8670.0341 | F7: =Funnel_24mo!F13*Assumptions!$B$7 -> 15285.438 | G7: =Funnel_24mo!G13*Assumptions!$B$7 -> 23303.525 | H7: =Funnel_24mo!H13*Assumptions!$B$7 -> 39423.169 | I7: =Funnel_24mo!I13*Assumptions!$B$7 -> 59768.474 | ... Y7: =Funnel_24mo!Y13*Assumptions!$B$7 -> 930076.36 | Z7: =SUM(B7:Y7) -> 7174110.6
A8: Subscription — Scale | B8: =Funnel_24mo!B14*Assumptions!$B$9 -> 269.82 | C8: =Funnel_24mo!C14*Assumptions!$B$9 -> 1452.9807 | D8: =Funnel_24mo!D14*Assumptions!$B$9 -> 3535.782 | E8: =Funnel_24mo!E14*Assumptions!$B$9 -> 8771.2173 | F8: =Funnel_24mo!F14*Assumptions!$B$9 -> 15533.55 | G8: =Funnel_24mo!G14*Assumptions!$B$9 -> 23799.877 | H8: =Funnel_24mo!H14*Assumptions!$B$9 -> 40306.629 | I8: =Funnel_24mo!I14*Assumptions!$B$9 -> 61287.629 | ... Y8: =Funnel_24mo!Y14*Assumptions!$B$9 -> 1020107.5 | Z8: =SUM(B8:Y8) -> 7705410.5
A9: Subscription subtotal | B9: =B6+B7+B8 -> 662.4 | C9: =C6+C7+C8 -> 3558.6657 | D9: =D6+D7+D8 -> 8627.2081 | E9: =E6+E7+E8 -> 21372.654 | F9: =F6+F7+F8 -> 37708.735 | G9: =G6+G7+G8 -> 57538.281 | H9: =H6+H7+H8 -> 97360.433 | I9: =I6+I7+I8 -> 147683.61 | ... Y9: =Y6+Y7+Y8 -> 2331161.6 | Z9: =SUM(B9:Y9) -> 17895589
A10: Overage revenue | B10: =B9*Assumptions!$B$72 -> 52.992 | C10: =C9*Assumptions!$B$72 -> 284.69326 | D10: =D9*Assumptions!$B$72 -> 690.17665 | E10: =E9*Assumptions!$B$72 -> 1709.8123 | F10: =F9*Assumptions!$B$72 -> 3016.6988 | G10: =G9*Assumptions!$B$72 -> 4603.0625 | H10: =H9*Assumptions!$B$72 -> 7788.8346 | I10: =I9*Assumptions!$B$72 -> 11814.689 | ... Y10: =Y9*Assumptions!$B$72 -> 186492.92 | Z10: =SUM(B10:Y10) -> 1431647.1
A11: TOTAL REVENUE | B11: =B9+B10 -> 715.392 | C11: =C9+C10 -> 3843.359 | D11: =D9+D10 -> 9317.3847 | E11: =E9+E10 -> 23082.466 | F11: =F9+F10 -> 40725.433 | G11: =G9+G10 -> 62141.343 | H11: =H9+H10 -> 105149.27 | I11: =I9+I10 -> 159498.3 | ... Y11: =Y9+Y10 -> 2517654.5 | Z11: =SUM(B11:Y11) -> 19327236
A12: COST OF GOODS SOLD
A13: Variable compute (verify volume) | B13: =Cost_Stack!B19 -> 7.378 | C13: =Cost_Stack!C19 -> 38.3393 | D13: =Cost_Stack!D19 -> 89.155714 | E13: =Cost_Stack!E19 -> 209.83528 | F13: =Cost_Stack!F19 -> 363.78802 | G13: =Cost_Stack!G19 -> 550.32168 | H13: =Cost_Stack!H19 -> 924.08671 | I13: =Cost_Stack!I19 -> 1395.256 | ... Y13: =Cost_Stack!Y19 -> 11070.835 | Z13: =SUM(B13:Y13) -> 86385.488
A14: Stripe processing | B14: =B11*Assumptions!$B$17 -> 20.746368 | C14: =C11*Assumptions!$B$17 -> 111.45741 | D14: =D11*Assumptions!$B$17 -> 270.20416 | E14: =E11*Assumptions!$B$17 -> 669.39152 | F14: =F11*Assumptions!$B$17 -> 1181.0376 | G14: =G11*Assumptions!$B$17 -> 1802.099 | H14: =H11*Assumptions!$B$17 -> 3049.3288 | I14: =I11*Assumptions!$B$17 -> 4625.4506 | ... Y14: =Y11*Assumptions!$B$17 -> 73011.98 | Z14: =SUM(B14:Y14) -> 560489.85
A15: TOTAL COGS | B15: =B13+B14 -> 28.124368 | C15: =C13+C14 -> 149.79671 | D15: =D13+D14 -> 359.35987 | E15: =E13+E14 -> 879.2268 | F15: =F13+F14 -> 1544.8256 | G15: =G13+G14 -> 2352.4206 | H15: =H13+H14 -> 3973.4155 | I15: =I13+I14 -> 6020.7065 | ... Y15: =Y13+Y14 -> 84082.815 | Z15: =SUM(B15:Y15) -> 646875.34
A16: GROSS PROFIT | B16: =B11-B15 -> 687.26763 | C16: =C11-C15 -> 3693.5622 | D16: =D11-D15 -> 8958.0249 | E16: =E11-E15 -> 22203.239 | F16: =F11-F15 -> 39180.608 | G16: =G11-G15 -> 59788.923 | H16: =H11-H15 -> 101175.85 | I16: =I11-I15 -> 153477.59 | ... Y16: =Y11-Y15 -> 2433571.7 | Z16: =SUM(B16:Y16) -> 18680361
A17: Gross margin % | B17: =IFERROR(B16/B11,0) -> 0.96068677 | C17: =IFERROR(C16/C11,0) -> 0.96102453 | D17: =IFERROR(D16/D11,0) -> 0.96143125 | E17: =IFERROR(E16/E11,0) -> 0.96190932 | F17: =IFERROR(F16/F11,0) -> 0.9620673 | G17: =IFERROR(G16/G11,0) -> 0.96214403 | H17: =IFERROR(H16/H11,0) -> 0.96221167 | I17: =IFERROR(I16/I11,0) -> 0.96225222 | ... Y17: =IFERROR(Y16/Y11,0) -> 0.96660272
A18: OPERATING EXPENSE (everything in Cost_Stack except variable COGS)
A19: Operator personal stack ($223 + $20 + API) | B19: =Cost_Stack!B6+Cost_Stack!B7+Cost_Stack!B8 -> 593 | C19: =Cost_Stack!C6+Cost_Stack!C7+Cost_Stack!C8 -> 593 | D19: =Cost_Stack!D6+Cost_Stack!D7+Cost_Stack!D8 -> 593 | E19: =Cost_Stack!E6+Cost_Stack!E7+Cost_Stack!E8 -> 593 | F19: =Cost_Stack!F6+Cost_Stack!F7+Cost_Stack!F8 -> 593 | G19: =Cost_Stack!G6+Cost_Stack!G7+Cost_Stack!G8 -> 593 | H19: =Cost_Stack!H6+Cost_Stack!H7+Cost_Stack!H8 -> 733 | I19: =Cost_Stack!I6+Cost_Stack!I7+Cost_Stack!I8 -> 733 | ... Y19: =Cost_Stack!Y6+Cost_Stack!Y7+Cost_Stack!Y8 -> 1203.4 | Z19: =SUM(B19:Y19) -> 20750.4
A20: KLYTICS shared infra (allocated) | B20: =Cost_Stack!B10 -> 136 | C20: =Cost_Stack!C10 -> 136 | D20: =Cost_Stack!D10 -> 136 | E20: =Cost_Stack!E10 -> 136 | F20: =Cost_Stack!F10 -> 136 | G20: =Cost_Stack!G10 -> 136 | H20: =Cost_Stack!H10 -> 136 | I20: =Cost_Stack!I10 -> 136 | ... Y20: =Cost_Stack!Y10 -> 136 | Z20: =SUM(B20:Y20) -> 3264
A21: AEGIS infra baseline | B21: =Cost_Stack!B12+Cost_Stack!B13+Cost_Stack!B14+Cost_Stack!B15+Cost_Stack!B16+Cost_Stack!B17 -> 546.03369 | C21: =Cost_Stack!C12+Cost_Stack!C13+Cost_Stack!C14+Cost_Stack!C15+Cost_Stack!C16+Cost_Stack!C17 -> 631.1999 | D21: =Cost_Stack!D12+Cost_Stack!D13+Cost_Stack!D14+Cost_Stack!D15+Cost_Stack!D16+Cost_Stack!D17 -> 699.61599 | E21: =Cost_Stack!E12+Cost_Stack!E13+Cost_Stack!E14+Cost_Stack!E15+Cost_Stack!E16+Cost_Stack!E17 -> 803.02481 | F21: =Cost_Stack!F12+Cost_Stack!F13+Cost_Stack!F14+Cost_Stack!F15+Cost_Stack!F16+Cost_Stack!F17 -> 896.19437 | G21: =Cost_Stack!G12+Cost_Stack!G13+Cost_Stack!G14+Cost_Stack!G15+Cost_Stack!G16+Cost_Stack!G17 -> 984.95243 | H21: =Cost_Stack!H12+Cost_Stack!H13+Cost_Stack!H14+Cost_Stack!H15+Cost_Stack!H16+Cost_Stack!H17 -> 1125.1066 | I21: =Cost_Stack!I12+Cost_Stack!I13+Cost_Stack!I14+Cost_Stack!I15+Cost_Stack!I16+Cost_Stack!I17 -> 1265.369 | ... Y21: =Cost_Stack!Y12+Cost_Stack!Y13+Cost_Stack!Y14+Cost_Stack!Y15+Cost_Stack!Y16+Cost_Stack!Y17 -> 1640 | Z21: =SUM(B21:Y21) -> 32861.184
A22: Headcount + contractors | B22: =Cost_Stack!B21+Cost_Stack!B22 -> 500 | C22: =Cost_Stack!C21+Cost_Stack!C22 -> 500 | D22: =Cost_Stack!D21+Cost_Stack!D22 -> 500 | E22: =Cost_Stack!E21+Cost_Stack!E22 -> 500 | F22: =Cost_Stack!F21+Cost_Stack!F22 -> 500 | G22: =Cost_Stack!G21+Cost_Stack!G22 -> 500 | H22: =Cost_Stack!H21+Cost_Stack!H22 -> 500 | I22: =Cost_Stack!I21+Cost_Stack!I22 -> 500 | ... Y22: =Cost_Stack!Y21+Cost_Stack!Y22 -> 2000 | Z22: =SUM(B22:Y22) -> 30000
A23: Sales & marketing | B23: =Cost_Stack!B24+Cost_Stack!B25 -> 500 | C23: =Cost_Stack!C24+Cost_Stack!C25 -> 500 | D23: =Cost_Stack!D24+Cost_Stack!D25 -> 500 | E23: =Cost_Stack!E24+Cost_Stack!E25 -> 500 | F23: =Cost_Stack!F24+Cost_Stack!F25 -> 500 | G23: =Cost_Stack!G24+Cost_Stack!G25 -> 500 | H23: =Cost_Stack!H24+Cost_Stack!H25 -> 1800 | I23: =Cost_Stack!I24+Cost_Stack!I25 -> 1800 | ... Y23: =Cost_Stack!Y24+Cost_Stack!Y25 -> 5300 | Z23: =SUM(B23:Y23) -> 77400
A24: TOTAL OPEX | B24: =B19+B20+B21+B22+B23 -> 2275.0337 | C24: =C19+C20+C21+C22+C23 -> 2360.1999 | D24: =D19+D20+D21+D22+D23 -> 2428.616 | E24: =E19+E20+E21+E22+E23 -> 2532.0248 | F24: =F19+F20+F21+F22+F23 -> 2625.1944 | G24: =G19+G20+G21+G22+G23 -> 2713.9524 | H24: =H19+H20+H21+H22+H23 -> 4294.1066 | I24: =I19+I20+I21+I22+I23 -> 4434.369 | ... Y24: =Y19+Y20+Y21+Y22+Y23 -> 10279.4 | Z24: =SUM(B24:Y24) -> 164275.58
A25: OPERATING INCOME (EBITDA proxy) | B25: =B16-B24 -> -1587.7661 | C25: =C16-C24 -> 1333.3623 | D25: =D16-D24 -> 6529.4089 | E25: =E16-E24 -> 19671.215 | F25: =F16-F24 -> 36555.413 | G25: =G16-G24 -> 57074.97 | H25: =H16-H24 -> 96881.745 | I25: =I16-I24 -> 149043.22 | ... Y25: =Y16-Y24 -> 2423292.3 | Z25: =SUM(B25:Y25) -> 18516085
A26: Tax (only on positive months) | B26: =MAX(0,B25)*Assumptions!$B$81 -> 0 | C26: =MAX(0,C25)*Assumptions!$B$81 -> 280.00609 | D26: =MAX(0,D25)*Assumptions!$B$81 -> 1371.1759 | E26: =MAX(0,E25)*Assumptions!$B$81 -> 4130.9551 | F26: =MAX(0,F25)*Assumptions!$B$81 -> 7676.6368 | G26: =MAX(0,G25)*Assumptions!$B$81 -> 11985.744 | H26: =MAX(0,H25)*Assumptions!$B$81 -> 20345.167 | I26: =MAX(0,I25)*Assumptions!$B$81 -> 31299.076 | ... Y26: =MAX(0,Y25)*Assumptions!$B$81 -> 508891.37 | Z26: =SUM(B26:Y26) -> 3888711.3
A27: NET INCOME | B27: =B25-B26 -> -1587.7661 | C27: =C25-C26 -> 1053.3563 | D27: =D25-D26 -> 5158.233 | E27: =E25-E26 -> 15540.26 | F27: =F25-F26 -> 28878.777 | G27: =G25-G26 -> 45089.226 | H27: =H25-H26 -> 76536.579 | I27: =I25-I26 -> 117744.14 | ... Y27: =Y25-Y26 -> 1914400.9 | Z27: =SUM(B27:Y27) -> 14627374

Sheet CashFlow_24mo
A1: Cash Flow — 24 months (operating cash + cumulative balance)
A2: Identifies the cash trough — the deepest cumulative drawdown the operator must cover.
A4: Line | B4: M01 | C4: M02 | D4: M03 | E4: M04 | F4: M05 | G4: M06 | H4: M07 | I4: M08 | J4: M09 | K4: M10 | L4: M11 | M4: M12 | N4: M13 | O4: M14 | P4: M15 | Q4: M16 | R4: M17 | S4: M18 | T4: M19 | U4: M20 | V4: M21 | W4: M22 | X4: M23 | Y4: M24 | Z4: 24mo total
A5: Net income (from PnL) | B5: =PnL_24mo!B27 -> -1587.7661 | C5: =PnL_24mo!C27 -> 1053.3563 | D5: =PnL_24mo!D27 -> 5158.233 | E5: =PnL_24mo!E27 -> 15540.26 | F5: =PnL_24mo!F27 -> 28878.777 | G5: =PnL_24mo!G27 -> 45089.226 | H5: =PnL_24mo!H27 -> 76536.579 | I5: =PnL_24mo!I27 -> 117744.14 | ... Y5: =PnL_24mo!Y27 -> 1914400.9 | Z5: =SUM(B5:Y5) -> 14627374
A6: Working-capital adjustment (revenue lag) | B6: =-PnL_24mo!B11*Assumptions!$B$83 -> -35.7696 | C6: =-PnL_24mo!C11*Assumptions!$B$83 -> -192.16795 | D6: =-PnL_24mo!D11*Assumptions!$B$83 -> -465.86924 | E6: =-PnL_24mo!E11*Assumptions!$B$83 -> -1154.1233 | F6: =-PnL_24mo!F11*Assumptions!$B$83 -> -2036.2717 | G6: =-PnL_24mo!G11*Assumptions!$B$83 -> -3107.0672 | H6: =-PnL_24mo!H11*Assumptions!$B$83 -> -5257.4634 | I6: =-PnL_24mo!I11*Assumptions!$B$83 -> -7974.9148 | ... Y6: =-PnL_24mo!Y11*Assumptions!$B$83 -> -125882.72 | Z6: =SUM(B6:Y6) -> -966361.81
A7: Operating cash flow | B7: =B5+B6 -> -1623.5357 | C7: =C5+C6 -> 861.18831 | D7: =D5+D6 -> 4692.3638 | E7: =E5+E6 -> 14386.136 | F7: =F5+F6 -> 26842.505 | G7: =G5+G6 -> 41982.159 | H7: =H5+H6 -> 71279.116 | I7: =I5+I6 -> 109769.23 | ... Y7: =Y5+Y6 -> 1788518.2 | Z7: =SUM(B7:Y7) -> 13661012
A8: Cumulative cash position | B8: =B7 -> -1623.5357 | C8: =B8+C7 -> -762.34735 | D8: =C8+D7 -> 3930.0164 | E8: =D8+E7 -> 18316.153 | F8: =E8+F7 -> 45158.658 | G8: =F8+G7 -> 87140.817 | H8: =G8+H7 -> 158419.93 | I8: =H8+I7 -> 268189.16 | J8: =I8+J7 -> 425061.08 | ... Y8: =X8+Y7 -> 13661012
A10: Trough month index (worst cumulative) | B10: =MATCH(MIN(B8:Y8),B8:Y8,0) -> 1
A11: Trough cash position (USD) | B11: =MIN(B8:Y8) -> -1623.5357
A12: Months to operating-cash break-even (first positive OCF month) | B12: =MATCH(TRUE(),INDEX(B7:Y7>0,0),0) -> 2

Sheet UnitEcon
A1: Unit Economics — per-customer LTV / CAC / payback
A3: Metric | B3: Dev | C3: Team | D3: Scale | E3: Blended | F3: Notes
A4: Monthly subscription price | B4: =Assumptions!$B$5 -> 49 | C4: =Assumptions!$B$7 -> 299 | D4: =Assumptions!$B$9 -> 1499 | E4: =B4*Assumptions!$B$60+C4*Assumptions!$B$61+D4*Assumptions!$B$62 -> 184 | F4: From Assumptions.
A5: Avg overage rev / customer / mo | B5: =B4*Assumptions!$B$72 -> 3.92 | C5: =C4*Assumptions!$B$72 -> 23.92 | D5: =D4*Assumptions!$B$72 -> 119.92 | E5: =B5*Assumptions!$B$60+C5*Assumptions!$B$61+D5*Assumptions!$B$62 -> 14.72 | F5: Subscription × overage share.
A6: Total monthly revenue / customer | B6: =B4+B5 -> 52.92 | C6: =C4+C5 -> 322.92 | D6: =D4+D5 -> 1618.92 | E6: =E4+E5 -> 198.72
A7: Variable compute / customer / mo | B7: =Assumptions!$B$69*1000*Assumptions!$B$15/1000000 -> 0.15 | C7: =Assumptions!$B$70*1000*Assumptions!$B$15/1000000 -> 1.75 | D7: =Assumptions!$B$71*1000*Assumptions!$B$15/1000000 -> 22.5 | E7: =B7*Assumptions!$B$60+C7*Assumptions!$B$61+D7*Assumptions!$B$62 -> 1.6675
A8: Stripe processing / customer / mo | B8: =B6*Assumptions!$B$17+Assumptions!$B$18 -> 1.83468 | C8: =C6*Assumptions!$B$17+Assumptions!$B$18 -> 9.66468 | D8: =D6*Assumptions!$B$17+Assumptions!$B$18 -> 47.24868 | E8: =E6*Assumptions!$B$17+Assumptions!$B$18 -> 6.06288
A9: Gross profit / customer / mo | B9: =B6-B7-B8 -> 50.93532 | C9: =C6-C7-C8 -> 311.50532 | D9: =D6-D7-D8 -> 1549.1713 | E9: =E6-E7-E8 -> 190.98962
A10: Gross margin % | B10: =IFERROR(B9/B6,0) -> 0.9624966 | C10: =IFERROR(C9/C6,0) -> 0.96465168 | D10: =IFERROR(D9/D6,0) -> 0.95691654 | E10: =IFERROR(E9/E6,0) -> 0.96109913
A11: Monthly logo churn | B11: =Assumptions!$B$63 -> 0.05 | C11: =Assumptions!$B$64 -> 0.03 | D11: =Assumptions!$B$65 -> 0.015 | E11: =B11*Assumptions!$B$60+C11*Assumptions!$B$61+D11*Assumptions!$B$62 -> 0.04325
A12: Avg customer lifetime (months) | B12: =IFERROR(1/B11,0) -> 20 | C12: =IFERROR(1/C11,0) -> 33.333333 | D12: =IFERROR(1/D11,0) -> 66.666667 | E12: =IFERROR(1/E11,0) -> 23.121387
A13: Net revenue retention (annualized) | B13: =Assumptions!$B$66 -> 1.05 | C13: =Assumptions!$B$67 -> 1.15 | D13: =Assumptions!$B$68 -> 1.25 | E13: =B13*Assumptions!$B$60+C13*Assumptions!$B$61+D13*Assumptions!$B$62 -> 1.085
A14: Simple LTV (gp/mo × lifetime, no NRR) | B14: =B9*B12 -> 1018.7064 | C14: =C9*C12 -> 10383.511 | D14: =D9*D12 -> 103278.09 | E14: =E9*E12 -> 4415.945
A15: NRR-adjusted LTV | B15: =B14*B13 -> 1069.6417 | C15: =C14*C13 -> 11941.037 | D15: =D14*D13 -> 129097.61 | E15: =E14*E13 -> 4791.3003
A16: PV LTV (discounted) | B16: =B15/(1+Assumptions!$B$82) -> 822.80132 | C16: =C15/(1+Assumptions!$B$82) -> 9185.4133 | D16: =D15/(1+Assumptions!$B$82) -> 99305.854 | E16: =E15/(1+Assumptions!$B$82) -> 3685.6156
A17: Blended LTV (used by Trial_Economics) | E17: =E16 -> 3685.6156
A18: CAC ceiling at 3x LTV/CAC target | B18: =B16/3 -> 274.26711 | C18: =C16/3 -> 3061.8044 | D18: =D16/3 -> 33101.951 | E18: =E16/3 -> 1228.5385
A19: Payback months @ break-even CAC | B19: =IFERROR(B18/B9,0) -> 5.3846154 | C19: =IFERROR(C18/C9,0) -> 9.8290598 | D19: =IFERROR(D18/D9,0) -> 21.367521 | E19: =IFERROR(E18/E9,0) -> 6.4324885

Sheet Scenarios
A1: Scenarios — Bear / Base / Bull side-by-side
A3: Active scenario (informational) | B3: Base
A5: Metric | B5: Bear | C5: Base | D5: Bull | E5: Notes
A6: Funnel multiplier | B6: =Assumptions!$B$75 -> 0.6 | C6: 1.00 | D6: =Assumptions!$B$77 -> 1.5 | E6: Applied to all monthly trial sign-ups.
A7: Conversion multiplier | B7: =Assumptions!$B$76 -> 0.7 | C7: 1.00 | D7: =Assumptions!$B$78 -> 1.2 | E7: Applied to steady-state conversion rate.
A8: Implied 24-mo trials | B8: =Funnel_24mo!Z5*B6 -> 50460 | C8: =Funnel_24mo!Z5 -> 84100 | D8: =Funnel_24mo!Z5*D6 -> 126150 | E8: Shows total free-trial sign-ups under each scenario.
A9: Implied 24-mo paid customers (cumulative new) | B9: =Funnel_24mo!Z7*B6*B7 -> 6278.3532 | C9: =Funnel_24mo!Z7 -> 14948.46 | D9: =Funnel_24mo!Z7*D6*D7 -> 26907.228 | E9: Multiplier compounds funnel × conversion.
A10: Implied 24-mo total revenue | B10: =PnL_24mo!Z11*B6*B7 -> 8117439.2 | C10: =PnL_24mo!Z11 -> 19327236 | D10: =PnL_24mo!Z11*D6*D7 -> 34789025 | E10: Linear approximation; exact scenario rebuild would re-run cohort math.
A11: Implied 24-mo total cost | B11: =PnL_24mo!Z24+PnL_24mo!Z15*B6*B7*0.6 -> 327288.17 | C11: =PnL_24mo!Z24+PnL_24mo!Z15 -> 811150.92 | D11: =PnL_24mo!Z24+PnL_24mo!Z15*D6*D7*1.4 -> 1794401.4 | E11: OpEx mostly fixed; COGS scales sub-linearly with traffic.
A12: Implied 24-mo net income | B12: =B9-B10 -> -8111160.9 | C12: =C9-C10 -> -19312288 | D12: =D9-D10 -> -34762118 | E12: Revenue − total cost. Approximation; for accurate scenario re-run, rebuild Funnel with multipliers.
A13: Implied trough cash position | B13: =CashFlow_24mo!B6*1.6 -> -57.23136 | C13: =CashFlow_24mo!B6 -> -35.7696 | D13: =CashFlow_24mo!B6*0.7 -> -25.03872 | E13: Cell ref reads trough; multipliers approximate scenario shift.
